Workbook

Sheet README
A1: PSX Momentum Investing Case Study — Workbook
A2: A Case Study of Momentum Investing on Selected PSX Stocks: Evaluating Rebalancing Frequency for Pakistani Retail Investors
A5: Data period: Jan 2015 – Dec 2024 (120 months). Original instructions stated Jan 2014; corrected after data review — no 2014 data exists in any source.
A7: Sheet guide:
A8: Raw_Prices Monthly close prices for 8 PSX stocks (source: FYP.xlsx, "Mutual Fund" placeholder column removed — out of scope)
A9: KSE100_Benchmark Monthly KSE-100 index level (source: Karachi_100_Historical_Data_1.csv, cleaned)
A10: RiskFree Monthly 3-Month T-Bill yield (source: data_series.csv, originally bi-weekly auction data)
A11: Returns Monthly simple returns for all 8 stocks + KSE-100, computed via formula from Raw_Prices/KSE100_Benchmark
A12: Assumptions All model assumptions: costs, CGT brackets, strategy parameters (single source of truth — referenced by formula in later sheets, not retyped)
A14: Data cleaning notes (see also project report, Data & Methodology section):
A15: 1. Raw_Prices dates: the source file stored the calendar month number in the "day" field of the date (a data entry artifact). Corrected so each row maps to the correct Year-Month.
A16: 2. KSE100_Benchmark: prices were stored as text with thousand-separator commas; converted to numeric.
... A18: 4. "Mutual fund" column in original FYP.xlsx was an empty placeholder for an out-of-scope dataset; removed entirely.

Sheet Assumptions
A1: Model Assumptions
A3: Strategy Parameters
A4: Formation Period (months) | B4: 6
A5: Holding Period (months) | B5: 12
A6: Portfolio Sizes (Top N) | B6: 2 / 3 / 5 | C6: Tested as separate scenarios
A7: Rebalancing Frequencies | B7: Annual / Semi-Annual / Quarterly | C7: Tested as separate scenarios
A8: Weighting Scheme | B8: Equal-weighted
A10: Trading Costs
A11: Brokerage (per trade, one-way) | B11: 0.0025 | C11: %
A12: CDC Charges (per trade, one-way) | B12: 0.001 | C12: %
A13: Total Transaction Cost (per trade) | B13: =B11+B12 -> 0.0035 | C13: Applied on buy and sell
A15: Capital Gains Tax (CGT)
A16: CGT — Holding < 1 year | B16: 0.15 | C16: Applies to positions closed before 12 full months
A17: CGT — Holding 1–2 years | B17: 0.125
A18: CGT — Holding > 2 years | B18: 0
A19: CGT convention for exactly 12-month holds | B19: Treated as < 1 year (15%) | C19: Documented assumption — strategy holding period is exactly 12 months, so this bracket choice is applied consistently across all scenarios
A21: Benchmark & Risk-Free
A22: Benchmark | B22: KSE-100 Index
A23: Risk-Free Rate | B23: 3-Month T-Bill (monthly, see RiskFree sheet)
A25: Sample Period
A26: Start | B26: Jan-2015 | C26: Corrected from Jan-2014 — no 2014 data available in source files
A27: End | B27: Dec-2024
A28: Number of months | B28: =COUNT(Raw_Prices!A2:A121) -> 120

Sheet Raw_Prices
A1: Date | B1: OGDC | C1: MEBL | D1: EFERT | E1: MCB | F1: LUCK | G1: FFC | H1: SAZEW | I1: MARI
A2: 42005 | B2: 210.51 | C2: 29.09 | D2: 85.49 | E2: 333.1 | F2: 521.99 | G2: 132.23 | H2: 11.84 | I2: 55.37
A3: 42036 | B3: 210.8 | C3: 28.45 | D3: 85.77 | E3: 307.97 | F3: 502.95 | G3: 141.44 | H3: 15.14 | I3: 48.85
A4: 42064 | B4: 181.5 | C4: 25.65 | D4: 77.14 | E4: 246.5 | F4: 446.04 | G4: 133.25 | H4: 13.35 | I4: 47.37
A5: 42095 | B5: 182.25 | C5: 25.6 | D5: 86.6 | E5: 276.1 | F5: 488 | G5: 142.5 | H5: 13.79 | I5: 50.14
A6: 42125 | B6: 184.5 | C6: 24.37 | D6: 84.15 | E6: 268.73 | F6: 448.65 | G6: 140.4 | H6: 12.75 | I6: 43
A7: 42156 | B7: 179.25 | C7: 23.85 | D7: 88.5 | E7: 248.75 | F7: 517.85 | G7: 150 | H7: 12.95 | I7: 43.16
A8: 42186 | B8: 163 | C8: 26.93 | D8: 92.8 | E8: 280 | F8: 555.5 | G8: 146.89 | H8: 13.56 | I8: 41.05
A9: 42217 | B9: 142.36 | C9: 28.85 | D9: 95.19 | E9: 253 | F9: 528 | G9: 137.51 | H9: 13.12 | I9: 37.38
A10: 42248 | B10: 125 | C10: 29.09 | D10: 89.49 | E10: 228 | F10: 525 | G10: 124.3 | H10: 10.83 | I10: 33.54
A11: 42278 | B11: 138 | C11: 27.4 | D11: 91.5 | E11: 245 | F11: 539.84 | G11: 125.7 | H11: 11.2 | I11: 38.7
A12: 42309 | B12: 121.4 | C12: 26.76 | D12: 81.5 | E12: 204.15 | F12: 480.5 | G12: 120.25 | H12: 10.11 | I12: 47.06
A13: 42339 | B13: 117.3 | C13: 26.61 | D13: 84.24 | E13: 217.95 | F13: 493 | G13: 118 | H13: 10.77 | I13: 64
... A121: 45627 | B121: 227.26 | C121: 241.97 | D121: 204.19 | E121: 281.3 | F121: 1100.49 | G121: 366.32 | H121: 1118.38 | I121: 719.61

Sheet KSE100_Benchmark
A1: Date | B1: KSE-100
A2: 42005 | B2: 34443.87
A3: 42036 | B3: 33632.19
A4: 42064 | B4: 30233.87
A5: 42095 | B5: 33729.96
A6: 42125 | B6: 33056.79
A7: 42156 | B7: 34398.86
A8: 42186 | B8: 35741.52
A9: 42217 | B9: 34726.51
A10: 42248 | B10: 32287.41
A11: 42278 | B11: 34261.6
A12: 42309 | B12: 32255.2
A13: 42339 | B13: 32816.31
... A121: 45627 | B121: 115126.9

Sheet RiskFree
A1: Date | B1: T-Bill 3M Yield (Annualized %) | D1: Note: converted from bi-weekly auction data — last observed yield per calendar month.
A2: 42005 | B2: 0.089217
A3: 42036 | B3: 0.083232
A4: 42064 | B4: 0.081578
A5: 42095 | B5: 0.073798
A6: 42125 | B6: 0.066055
A7: 42156 | B7: 0.068637
A8: 42186 | B8: 0.06919
A9: 42217 | B9: 0.069308
A10: 42248 | B10: 0.064663
A11: 42278 | B11: 0.063038
A12: 42309 | B12: 0.063691
A13: 42339 | B13: 0.063374
... A121: 45627 | B121: 0.1185

Sheet Returns
A1: Date | B1: OGDC | C1: MEBL | D1: EFERT | E1: MCB | F1: LUCK | G1: FFC | H1: SAZEW | I1: MARI | J1: KSE-100 | L1: Row 2 (Jan-2015) is blank — no prior month to compute return from.
A2: =Raw_Prices!A2 -> 42005
A3: =Raw_Prices!A3 -> 42036 | B3: =Raw_Prices!B3/Raw_Prices!B2-1 -> 0.0013776068 | C3: =Raw_Prices!C3/Raw_Prices!C2-1 -> -0.022000688 | D3: =Raw_Prices!D3/Raw_Prices!D2-1 -> 0.0032752369 | E3: =Raw_Prices!E3/Raw_Prices!E2-1 -> -0.07544281 | F3: =Raw_Prices!F3/Raw_Prices!F2-1 -> -0.036475795 | G3: =Raw_Prices!G3/Raw_Prices!G2-1 -> 0.069651365 | H3: =Raw_Prices!H3/Raw_Prices!H2-1 -> 0.27871622 | I3: =Raw_Prices!I3/Raw_Prices!I2-1 -> -0.1177533 | J3: =KSE100_Benchmark!B3/KSE100_Benchmark!B2-1 -> -0.023565296
A4: =Raw_Prices!A4 -> 42064 | B4: =Raw_Prices!B4/Raw_Prices!B3-1 -> -0.13899431 | C4: =Raw_Prices!C4/Raw_Prices!C3-1 -> -0.098418278 | D4: =Raw_Prices!D4/Raw_Prices!D3-1 -> -0.10061793 | E4: =Raw_Prices!E4/Raw_Prices!E3-1 -> -0.19959736 | F4: =Raw_Prices!F4/Raw_Prices!F3-1 -> -0.1131524 | G4: =Raw_Prices!G4/Raw_Prices!G3-1 -> -0.057904412 | H4: =Raw_Prices!H4/Raw_Prices!H3-1 -> -0.11822985 | I4: =Raw_Prices!I4/Raw_Prices!I3-1 -> -0.030296827 | J4: =KSE100_Benchmark!B4/KSE100_Benchmark!B3-1 -> -0.10104367
A5: =Raw_Prices!A5 -> 42095 | B5: =Raw_Prices!B5/Raw_Prices!B4-1 -> 0.0041322314 | C5: =Raw_Prices!C5/Raw_Prices!C4-1 -> -0.0019493177 | D5: =Raw_Prices!D5/Raw_Prices!D4-1 -> 0.12263417 | E5: =Raw_Prices!E5/Raw_Prices!E4-1 -> 0.12008114 | F5: =Raw_Prices!F5/Raw_Prices!F4-1 -> 0.094072281 | G5: =Raw_Prices!G5/Raw_Prices!G4-1 -> 0.069418386 | H5: =Raw_Prices!H5/Raw_Prices!H4-1 -> 0.032958801 | I5: =Raw_Prices!I5/Raw_Prices!I4-1 -> 0.058475829 | J5: =KSE100_Benchmark!B5/KSE100_Benchmark!B4-1 -> 0.11563488
A6: =Raw_Prices!A6 -> 42125 | B6: =Raw_Prices!B6/Raw_Prices!B5-1 -> 0.012345679 | C6: =Raw_Prices!C6/Raw_Prices!C5-1 -> -0.048046875 | D6: =Raw_Prices!D6/Raw_Prices!D5-1 -> -0.028290993 | E6: =Raw_Prices!E6/Raw_Prices!E5-1 -> -0.026693227 | F6: =Raw_Prices!F6/Raw_Prices!F5-1 -> -0.080635246 | G6: =Raw_Prices!G6/Raw_Prices!G5-1 -> -0.014736842 | H6: =Raw_Prices!H6/Raw_Prices!H5-1 -> -0.075416969 | I6: =Raw_Prices!I6/Raw_Prices!I5-1 -> -0.14240128 | J6: =KSE100_Benchmark!B6/KSE100_Benchmark!B5-1 -> -0.019957628
A7: =Raw_Prices!A7 -> 42156 | B7: =Raw_Prices!B7/Raw_Prices!B6-1 -> -0.028455285 | C7: =Raw_Prices!C7/Raw_Prices!C6-1 -> -0.02133771 | D7: =Raw_Prices!D7/Raw_Prices!D6-1 -> 0.051693405 | E7: =Raw_Prices!E7/Raw_Prices!E6-1 -> -0.074349719 | F7: =Raw_Prices!F7/Raw_Prices!F6-1 -> 0.1542405 | G7: =Raw_Prices!G7/Raw_Prices!G6-1 -> 0.068376068 | H7: =Raw_Prices!H7/Raw_Prices!H6-1 -> 0.015686275 | I7: =Raw_Prices!I7/Raw_Prices!I6-1 -> 0.0037209302 | J7: =KSE100_Benchmark!B7/KSE100_Benchmark!B6-1 -> 0.040598921
A8: =Raw_Prices!A8 -> 42186 | B8: =Raw_Prices!B8/Raw_Prices!B7-1 -> -0.090655509 | C8: =Raw_Prices!C8/Raw_Prices!C7-1 -> 0.12914046 | D8: =Raw_Prices!D8/Raw_Prices!D7-1 -> 0.048587571 | E8: =Raw_Prices!E8/Raw_Prices!E7-1 -> 0.12562814 | F8: =Raw_Prices!F8/Raw_Prices!F7-1 -> 0.072704451 | G8: =Raw_Prices!G8/Raw_Prices!G7-1 -> -0.020733333 | H8: =Raw_Prices!H8/Raw_Prices!H7-1 -> 0.047104247 | I8: =Raw_Prices!I8/Raw_Prices!I7-1 -> -0.048887859 | J8: =KSE100_Benchmark!B8/KSE100_Benchmark!B7-1 -> 0.039032107
A9: =Raw_Prices!A9 -> 42217 | B9: =Raw_Prices!B9/Raw_Prices!B8-1 -> -0.12662577 | C9: =Raw_Prices!C9/Raw_Prices!C8-1 -> 0.071295952 | D9: =Raw_Prices!D9/Raw_Prices!D8-1 -> 0.02575431 | E9: =Raw_Prices!E9/Raw_Prices!E8-1 -> -0.096428571 | F9: =Raw_Prices!F9/Raw_Prices!F8-1 -> -0.04950495 | G9: =Raw_Prices!G9/Raw_Prices!G8-1 -> -0.063857308 | H9: =Raw_Prices!H9/Raw_Prices!H8-1 -> -0.032448378 | I9: =Raw_Prices!I9/Raw_Prices!I8-1 -> -0.089403167 | J9: =KSE100_Benchmark!B9/KSE100_Benchmark!B8-1 -> -0.028398624
A10: =Raw_Prices!A10 -> 42248 | B10: =Raw_Prices!B10/Raw_Prices!B9-1 -> -0.12194437 | C10: =Raw_Prices!C10/Raw_Prices!C9-1 -> 0.0083188908 | D10: =Raw_Prices!D10/Raw_Prices!D9-1 -> -0.05988024 | E10: =Raw_Prices!E10/Raw_Prices!E9-1 -> -0.098814229 | F10: =Raw_Prices!F10/Raw_Prices!F9-1 -> -0.0056818182 | G10: =Raw_Prices!G10/Raw_Prices!G9-1 -> -0.096065741 | H10: =Raw_Prices!H10/Raw_Prices!H9-1 -> -0.17454268 | I10: =Raw_Prices!I10/Raw_Prices!I9-1 -> -0.10272873 | J10: =KSE100_Benchmark!B10/KSE100_Benchmark!B9-1 -> -0.070237407
A11: =Raw_Prices!A11 -> 42278 | B11: =Raw_Prices!B11/Raw_Prices!B10-1 -> 0.104 | C11: =Raw_Prices!C11/Raw_Prices!C10-1 -> -0.058095565 | D11: =Raw_Prices!D11/Raw_Prices!D10-1 -> 0.02246061 | E11: =Raw_Prices!E11/Raw_Prices!E10-1 -> 0.074561404 | F11: =Raw_Prices!F11/Raw_Prices!F10-1 -> 0.028266667 | G11: =Raw_Prices!G11/Raw_Prices!G10-1 -> 0.011263073 | H11: =Raw_Prices!H11/Raw_Prices!H10-1 -> 0.034164358 | I11: =Raw_Prices!I11/Raw_Prices!I10-1 -> 0.15384615 | J11: =KSE100_Benchmark!B11/KSE100_Benchmark!B10-1 -> 0.061144266
A12: =Raw_Prices!A12 -> 42309 | B12: =Raw_Prices!B12/Raw_Prices!B11-1 -> -0.12028986 | C12: =Raw_Prices!C12/Raw_Prices!C11-1 -> -0.023357664 | D12: =Raw_Prices!D12/Raw_Prices!D11-1 -> -0.10928962 | E12: =Raw_Prices!E12/Raw_Prices!E11-1 -> -0.16673469 | F12: =Raw_Prices!F12/Raw_Prices!F11-1 -> -0.10992146 | G12: =Raw_Prices!G12/Raw_Prices!G11-1 -> -0.0433572 | H12: =Raw_Prices!H12/Raw_Prices!H11-1 -> -0.097321429 | I12: =Raw_Prices!I12/Raw_Prices!I11-1 -> 0.21602067 | J12: =KSE100_Benchmark!B12/KSE100_Benchmark!B11-1 -> -0.058561188
A13: =Raw_Prices!A13 -> 42339 | B13: =Raw_Prices!B13/Raw_Prices!B12-1 -> -0.033772652 | C13: =Raw_Prices!C13/Raw_Prices!C12-1 -> -0.0056053812 | D13: =Raw_Prices!D13/Raw_Prices!D12-1 -> 0.033619632 | E13: =Raw_Prices!E13/Raw_Prices!E12-1 -> 0.067597355 | F13: =Raw_Prices!F13/Raw_Prices!F12-1 -> 0.026014568 | G13: =Raw_Prices!G13/Raw_Prices!G12-1 -> -0.018711019 | H13: =Raw_Prices!H13/Raw_Prices!H12-1 -> 0.065281899 | I13: =Raw_Prices!I13/Raw_Prices!I12-1 -> 0.359966 | J13: =KSE100_Benchmark!B13/KSE100_Benchmark!B12-1 -> 0.017395955
A14: =Raw_Prices!A14 -> 42370 | B14: =Raw_Prices!B14/Raw_Prices!B13-1 -> -0.070758738 | C14: =Raw_Prices!C14/Raw_Prices!C13-1 -> -0.049229613 | D14: =Raw_Prices!D14/Raw_Prices!D13-1 -> -0.053181387 | E14: =Raw_Prices!E14/Raw_Prices!E13-1 -> -0.1144758 | F14: =Raw_Prices!F14/Raw_Prices!F13-1 -> -0.020263692 | G14: =Raw_Prices!G14/Raw_Prices!G13-1 -> -0.058389831 | H14: =Raw_Prices!H14/Raw_Prices!H13-1 -> -0.078922934 | I14: =Raw_Prices!I14/Raw_Prices!I13-1 -> -0.1190625 | J14: =KSE100_Benchmark!B14/KSE100_Benchmark!B13-1 -> -0.046248649
... A121: =Raw_Prices!A121 -> 45627 | B121: =Raw_Prices!B121/Raw_Prices!B120-1 -> 0.16394366 | C121: =Raw_Prices!C121/Raw_Prices!C120-1 -> 0.064165714 | D121: =Raw_Prices!D121/Raw_Prices!D120-1 -> 0.019879127 | E121: =Raw_Prices!E121/Raw_Prices!E120-1 -> 0.03701246 | F121: =Raw_Prices!F121/Raw_Prices!F120-1 -> 0.079387965 | G121: =Raw_Prices!G121/Raw_Prices!G120-1 -> 0.12752008 | H121: =Raw_Prices!H121/Raw_Prices!H120-1 -> 0.11338092 | I121: =Raw_Prices!I121/Raw_Prices!I120-1 -> 0.55685604 | J121: =KSE100_Benchmark!B121/KSE100_Benchmark!B120-1 -> 0.13585186

Sheet Momentum_Signal
A1: 6-Month Trailing Formation Return (Momentum Signal)
A2: Signal at month i = cumulative return over months (i-5) to i. First available i=7 (Jul-2015), needs 6 prior monthly returns.
A4: Month (i) | B4: Date | C4: OGDC | D4: MEBL | E4: EFERT | F4: MCB | G4: LUCK | H4: FFC | I4: SAZEW | J4: MARI
A5: 1 | B5: =Returns!A2 -> 42005
A6: 2 | B6: =Returns!A3 -> 42036
A7: 3 | B7: =Returns!A4 -> 42064
A8: 4 | B8: =Returns!A5 -> 42095
A9: 5 | B9: =Returns!A6 -> 42125
A10: 6 | B10: =Returns!A7 -> 42156
A11: 7 | B11: =Returns!A8 -> 42186 | C11: =(1+Returns!C3)*(1+Returns!C4)*(1+Returns!C5)*(1+Returns!C6)*(1+Returns!C7)*(1+Returns!C8)-1 -> -0.07425232 | D11: =(1+Returns!D3)*(1+Returns!D4)*(1+Returns!D5)*(1+Returns!D6)*(1+Returns!D7)*(1+Returns!D8)-1 -> 0.085507077 | E11: =(1+Returns!E3)*(1+Returns!E4)*(1+Returns!E5)*(1+Returns!E6)*(1+Returns!E7)*(1+Returns!E8)-1 -> -0.15941159 | F11: =(1+Returns!F3)*(1+Returns!F4)*(1+Returns!F5)*(1+Returns!F6)*(1+Returns!F7)*(1+Returns!F8)-1 -> 0.064196632 | G11: =(1+Returns!G3)*(1+Returns!G4)*(1+Returns!G5)*(1+Returns!G6)*(1+Returns!G7)*(1+Returns!G8)-1 -> 0.11086743 | H11: =(1+Returns!H3)*(1+Returns!H4)*(1+Returns!H5)*(1+Returns!H6)*(1+Returns!H7)*(1+Returns!H8)-1 -> 0.14527027 | I11: =(1+Returns!I3)*(1+Returns!I4)*(1+Returns!I5)*(1+Returns!I6)*(1+Returns!I7)*(1+Returns!I8)-1 -> -0.2586238 | J11: =(1+Returns!J3)*(1+Returns!J4)*(1+Returns!J5)*(1+Returns!J6)*(1+Returns!J7)*(1+Returns!J8)-1 -> 0.037674338
A12: 8 | B12: =Returns!A9 -> 42217 | C12: =(1+Returns!C4)*(1+Returns!C5)*(1+Returns!C6)*(1+Returns!C7)*(1+Returns!C8)*(1+Returns!C9)-1 -> 0.014059754 | D12: =(1+Returns!D4)*(1+Returns!D5)*(1+Returns!D6)*(1+Returns!D7)*(1+Returns!D8)*(1+Returns!D9)-1 -> 0.10982861 | E12: =(1+Returns!E4)*(1+Returns!E5)*(1+Returns!E6)*(1+Returns!E7)*(1+Returns!E8)*(1+Returns!E9)-1 -> -0.17849141 | F12: =(1+Returns!F4)*(1+Returns!F5)*(1+Returns!F6)*(1+Returns!F7)*(1+Returns!F8)*(1+Returns!F9)-1 -> 0.049806144 | G12: =(1+Returns!G4)*(1+Returns!G5)*(1+Returns!G6)*(1+Returns!G7)*(1+Returns!G8)*(1+Returns!G9)-1 -> -0.027785633 | H12: =(1+Returns!H4)*(1+Returns!H5)*(1+Returns!H6)*(1+Returns!H7)*(1+Returns!H8)*(1+Returns!H9)-1 -> -0.1334214 | I12: =(1+Returns!I4)*(1+Returns!I5)*(1+Returns!I6)*(1+Returns!I7)*(1+Returns!I8)*(1+Returns!I9)-1 -> -0.23480041 | J12: =(1+Returns!J4)*(1+Returns!J5)*(1+Returns!J6)*(1+Returns!J7)*(1+Returns!J8)*(1+Returns!J9)-1 -> 0.032537875
A13: 9 | B13: =Returns!A10 -> 42248 | C13: =(1+Returns!C5)*(1+Returns!C6)*(1+Returns!C7)*(1+Returns!C8)*(1+Returns!C9)*(1+Returns!C10)-1 -> 0.13411306 | D13: =(1+Returns!D5)*(1+Returns!D6)*(1+Returns!D7)*(1+Returns!D8)*(1+Returns!D9)*(1+Returns!D10)-1 -> 0.16009852 | E13: =(1+Returns!E5)*(1+Returns!E6)*(1+Returns!E7)*(1+Returns!E8)*(1+Returns!E9)*(1+Returns!E10)-1 -> -0.07505071 | F13: =(1+Returns!F5)*(1+Returns!F6)*(1+Returns!F7)*(1+Returns!F8)*(1+Returns!F9)*(1+Returns!F10)-1 -> 0.17702448 | G13: =(1+Returns!G5)*(1+Returns!G6)*(1+Returns!G7)*(1+Returns!G8)*(1+Returns!G9)*(1+Returns!G10)-1 -> -0.067166979 | H13: =(1+Returns!H5)*(1+Returns!H6)*(1+Returns!H7)*(1+Returns!H8)*(1+Returns!H9)*(1+Returns!H10)-1 -> -0.18876404 | I13: =(1+Returns!I5)*(1+Returns!I6)*(1+Returns!I7)*(1+Returns!I8)*(1+Returns!I9)*(1+Returns!I10)-1 -> -0.29195693 | J13: =(1+Returns!J5)*(1+Returns!J6)*(1+Returns!J7)*(1+Returns!J8)*(1+Returns!J9)*(1+Returns!J10)-1 -> 0.067921837
A14: 10 | B14: =Returns!A11 -> 42278 | C14: =(1+Returns!C6)*(1+Returns!C7)*(1+Returns!C8)*(1+Returns!C9)*(1+Returns!C10)*(1+Returns!C11)-1 -> 0.0703125 | D14: =(1+Returns!D6)*(1+Returns!D7)*(1+Returns!D8)*(1+Returns!D9)*(1+Returns!D10)*(1+Returns!D11)-1 -> 0.056581986 | E14: =(1+Returns!E6)*(1+Returns!E7)*(1+Returns!E8)*(1+Returns!E9)*(1+Returns!E10)*(1+Returns!E11)-1 -> -0.11264035 | F14: =(1+Returns!F6)*(1+Returns!F7)*(1+Returns!F8)*(1+Returns!F9)*(1+Returns!F10)*(1+Returns!F11)-1 -> 0.10622951 | G14: =(1+Returns!G6)*(1+Returns!G7)*(1+Returns!G8)*(1+Returns!G9)*(1+Returns!G10)*(1+Returns!G11)-1 -> -0.11789474 | H14: =(1+Returns!H6)*(1+Returns!H7)*(1+Returns!H8)*(1+Returns!H9)*(1+Returns!H10)*(1+Returns!H11)-1 -> -0.18781726 | I14: =(1+Returns!I6)*(1+Returns!I7)*(1+Returns!I8)*(1+Returns!I9)*(1+Returns!I10)*(1+Returns!I11)-1 -> -0.22816115 | J14: =(1+Returns!J6)*(1+Returns!J7)*(1+Returns!J8)*(1+Returns!J9)*(1+Returns!J10)*(1+Returns!J11)-1 -> 0.015761655
A15: 11 | B15: =Returns!A12 -> 42309 | C15: =(1+Returns!C7)*(1+Returns!C8)*(1+Returns!C9)*(1+Returns!C10)*(1+Returns!C11)*(1+Returns!C12)-1 -> 0.098071399 | D15: =(1+Returns!D7)*(1+Returns!D8)*(1+Returns!D9)*(1+Returns!D10)*(1+Returns!D11)*(1+Returns!D12)-1 -> -0.031491384 | E15: =(1+Returns!E7)*(1+Returns!E8)*(1+Returns!E9)*(1+Returns!E10)*(1+Returns!E11)*(1+Returns!E12)-1 -> -0.24031556 | F15: =(1+Returns!F7)*(1+Returns!F8)*(1+Returns!F9)*(1+Returns!F10)*(1+Returns!F11)*(1+Returns!F12)-1 -> 0.07099075 | G15: =(1+Returns!G7)*(1+Returns!G8)*(1+Returns!G9)*(1+Returns!G10)*(1+Returns!G11)*(1+Returns!G12)-1 -> -0.14351852 | H15: =(1+Returns!H7)*(1+Returns!H8)*(1+Returns!H9)*(1+Returns!H10)*(1+Returns!H11)*(1+Returns!H12)-1 -> -0.20705882 | I15: =(1+Returns!I7)*(1+Returns!I8)*(1+Returns!I9)*(1+Returns!I10)*(1+Returns!I11)*(1+Returns!I12)-1 -> 0.094418605 | J15: =(1+Returns!J7)*(1+Returns!J8)*(1+Returns!J9)*(1+Returns!J10)*(1+Returns!J11)*(1+Returns!J12)-1 -> -0.024248876
A16: 12 | B16: =Returns!A13 -> 42339 | C16: =(1+Returns!C8)*(1+Returns!C9)*(1+Returns!C10)*(1+Returns!C11)*(1+Returns!C12)*(1+Returns!C13)-1 -> 0.11572327 | D16: =(1+Returns!D8)*(1+Returns!D9)*(1+Returns!D10)*(1+Returns!D11)*(1+Returns!D12)*(1+Returns!D13)-1 -> -0.048135593 | E16: =(1+Returns!E8)*(1+Returns!E9)*(1+Returns!E10)*(1+Returns!E11)*(1+Returns!E12)*(1+Returns!E13)-1 -> -0.1238191 | F16: =(1+Returns!F8)*(1+Returns!F9)*(1+Returns!F10)*(1+Returns!F11)*(1+Returns!F12)*(1+Returns!F13)-1 -> -0.047986869 | G16: =(1+Returns!G8)*(1+Returns!G9)*(1+Returns!G10)*(1+Returns!G11)*(1+Returns!G12)*(1+Returns!G13)-1 -> -0.21333333 | H16: =(1+Returns!H8)*(1+Returns!H9)*(1+Returns!H10)*(1+Returns!H11)*(1+Returns!H12)*(1+Returns!H13)-1 -> -0.16833977 | I16: =(1+Returns!I8)*(1+Returns!I9)*(1+Returns!I10)*(1+Returns!I11)*(1+Returns!I12)*(1+Returns!I13)-1 -> 0.48285449 | J16: =(1+Returns!J8)*(1+Returns!J9)*(1+Returns!J10)*(1+Returns!J11)*(1+Returns!J12)*(1+Returns!J13)-1 -> -0.046005885
A17: 13 | B17: =Returns!A14 -> 42370 | C17: =(1+Returns!C9)*(1+Returns!C10)*(1+Returns!C11)*(1+Returns!C12)*(1+Returns!C13)*(1+Returns!C14)-1 -> -0.060527293 | D17: =(1+Returns!D9)*(1+Returns!D10)*(1+Returns!D11)*(1+Returns!D12)*(1+Returns!D13)*(1+Returns!D14)-1 -> -0.14051724 | E17: =(1+Returns!E9)*(1+Returns!E10)*(1+Returns!E11)*(1+Returns!E12)*(1+Returns!E13)*(1+Returns!E14)-1 -> -0.31071429 | F17: =(1+Returns!F9)*(1+Returns!F10)*(1+Returns!F11)*(1+Returns!F12)*(1+Returns!F13)*(1+Returns!F14)-1 -> -0.13049505 | G17: =(1+Returns!G9)*(1+Returns!G10)*(1+Returns!G11)*(1+Returns!G12)*(1+Returns!G13)*(1+Returns!G14)-1 -> -0.24358363 | H17: =(1+Returns!H9)*(1+Returns!H10)*(1+Returns!H11)*(1+Returns!H12)*(1+Returns!H13)*(1+Returns!H14)-1 -> -0.26843658 | I17: =(1+Returns!I9)*(1+Returns!I10)*(1+Returns!I11)*(1+Returns!I12)*(1+Returns!I13)*(1+Returns!I14)-1 -> 0.37344702 | J17: =(1+Returns!J9)*(1+Returns!J10)*(1+Returns!J11)*(1+Returns!J12)*(1+Returns!J13)*(1+Returns!J14)-1 -> -0.12430697
A18: 14 | B18: =Returns!A15 -> 42401 | C18: =(1+Returns!C10)*(1+Returns!C11)*(1+Returns!C12)*(1+Returns!C13)*(1+Returns!C14)*(1+Returns!C15)-1 -> -0.15632582 | D18: =(1+Returns!D10)*(1+Returns!D11)*(1+Returns!D12)*(1+Returns!D13)*(1+Returns!D14)*(1+Returns!D15)-1 -> -0.2081101 | E18: =(1+Returns!E10)*(1+Returns!E11)*(1+Returns!E12)*(1+Returns!E13)*(1+Returns!E14)*(1+Returns!E15)-1 -> -0.22687747 | F18: =(1+Returns!F10)*(1+Returns!F11)*(1+Returns!F12)*(1+Returns!F13)*(1+Returns!F14)*(1+Returns!F15)-1 -> -0.070833333 | G18: =(1+Returns!G10)*(1+Returns!G11)*(1+Returns!G12)*(1+Returns!G13)*(1+Returns!G14)*(1+Returns!G15)-1 -> -0.21023926 | H18: =(1+Returns!H10)*(1+Returns!H11)*(1+Returns!H12)*(1+Returns!H13)*(1+Returns!H14)*(1+Returns!H15)-1 -> -0.27057927 | I18: =(1+Returns!I10)*(1+Returns!I11)*(1+Returns!I12)*(1+Returns!I13)*(1+Returns!I14)*(1+Returns!I15)-1 -> 0.42536116 | J18: =(1+Returns!J10)*(1+Returns!J11)*(1+Returns!J12)*(1+Returns!J13)*(1+Returns!J14)*(1+Returns!J15)-1 -> -0.096669662
A19: 15 | B19: =Returns!A16 -> 42430 | C19: =(1+Returns!C11)*(1+Returns!C12)*(1+Returns!C13)*(1+Returns!C14)*(1+Returns!C15)*(1+Returns!C16)-1 -> -0.16019251 | D19: =(1+Returns!D11)*(1+Returns!D12)*(1+Returns!D13)*(1+Returns!D14)*(1+Returns!D15)*(1+Returns!D16)-1 -> -0.22449436 | E19: =(1+Returns!E11)*(1+Returns!E12)*(1+Returns!E13)*(1+Returns!E14)*(1+Returns!E15)*(1+Returns!E16)-1 -> -0.096447368 | F19: =(1+Returns!F11)*(1+Returns!F12)*(1+Returns!F13)*(1+Returns!F14)*(1+Returns!F15)*(1+Returns!F16)-1 -> 0.022857143 | G19: =(1+Returns!G11)*(1+Returns!G12)*(1+Returns!G13)*(1+Returns!G14)*(1+Returns!G15)*(1+Returns!G16)-1 -> -0.14432824 | H19: =(1+Returns!H11)*(1+Returns!H12)*(1+Returns!H13)*(1+Returns!H14)*(1+Returns!H15)*(1+Returns!H16)-1 -> -0.046168052 | I19: =(1+Returns!I11)*(1+Returns!I12)*(1+Returns!I13)*(1+Returns!I14)*(1+Returns!I15)*(1+Returns!I16)-1 -> 0.92397138 | J19: =(1+Returns!J11)*(1+Returns!J12)*(1+Returns!J13)*(1+Returns!J14)*(1+Returns!J15)*(1+Returns!J16)-1 -> 0.026375296
A20: 16 | B20: =Returns!A17 -> 42461 | C20: =(1+Returns!C12)*(1+Returns!C13)*(1+Returns!C14)*(1+Returns!C15)*(1+Returns!C16)*(1+Returns!C17)-1 -> -0.10948905 | D20: =(1+Returns!D12)*(1+Returns!D13)*(1+Returns!D14)*(1+Returns!D15)*(1+Returns!D16)*(1+Returns!D17)-1 -> -0.23715847 | E20: =(1+Returns!E12)*(1+Returns!E13)*(1+Returns!E14)*(1+Returns!E15)*(1+Returns!E16)*(1+Returns!E17)-1 -> -0.13538776 | F20: =(1+Returns!F12)*(1+Returns!F13)*(1+Returns!F14)*(1+Returns!F15)*(1+Returns!F16)*(1+Returns!F17)-1 -> 0.023451393 | G20: =(1+Returns!G12)*(1+Returns!G13)*(1+Returns!G14)*(1+Returns!G15)*(1+Returns!G16)*(1+Returns!G17)-1 -> -0.14868735 | H20: =(1+Returns!H12)*(1+Returns!H13)*(1+Returns!H14)*(1+Returns!H15)*(1+Returns!H16)*(1+Returns!H17)-1 -> 0.021428571 | I20: =(1+Returns!I12)*(1+Returns!I13)*(1+Returns!I14)*(1+Returns!I15)*(1+Returns!I16)*(1+Returns!I17)-1 -> 0.79844961 | J20: =(1+Returns!J12)*(1+Returns!J13)*(1+Returns!J14)*(1+Returns!J15)*(1+Returns!J16)*(1+Returns!J17)-1 -> 0.013358687
A21: 17 | B21: =Returns!A18 -> 42491 | C21: =(1+Returns!C13)*(1+Returns!C14)*(1+Returns!C15)*(1+Returns!C16)*(1+Returns!C17)*(1+Returns!C18)-1 -> -0.097907324 | D21: =(1+Returns!D13)*(1+Returns!D14)*(1+Returns!D15)*(1+Returns!D16)*(1+Returns!D17)*(1+Returns!D18)-1 -> -0.1403681 | E21: =(1+Returns!E13)*(1+Returns!E14)*(1+Returns!E15)*(1+Returns!E16)*(1+Returns!E17)*(1+Returns!E18)-1 -> 0.013960323 | F21: =(1+Returns!F13)*(1+Returns!F14)*(1+Returns!F15)*(1+Returns!F16)*(1+Returns!F17)*(1+Returns!F18)-1 -> 0.23621228 | G21: =(1+Returns!G13)*(1+Returns!G14)*(1+Returns!G15)*(1+Returns!G16)*(1+Returns!G17)*(1+Returns!G18)-1 -> -0.054054054 | H21: =(1+Returns!H13)*(1+Returns!H14)*(1+Returns!H15)*(1+Returns!H16)*(1+Returns!H17)*(1+Returns!H18)-1 -> 0.043521266 | I21: =(1+Returns!I13)*(1+Returns!I14)*(1+Returns!I15)*(1+Returns!I16)*(1+Returns!I17)*(1+Returns!I18)-1 -> 0.71716957 | J21: =(1+Returns!J13)*(1+Returns!J14)*(1+Returns!J15)*(1+Returns!J16)*(1+Returns!J17)*(1+Returns!J18)-1 -> 0.11800764
A22: 18 | B22: =Returns!A19 -> 42522 | C22: =(1+Returns!C14)*(1+Returns!C15)*(1+Returns!C16)*(1+Returns!C17)*(1+Returns!C18)*(1+Returns!C19)-1 -> -0.07102593 | D22: =(1+Returns!D14)*(1+Returns!D15)*(1+Returns!D16)*(1+Returns!D17)*(1+Returns!D18)*(1+Returns!D19)-1 -> -0.23433048 | E22: =(1+Returns!E14)*(1+Returns!E15)*(1+Returns!E16)*(1+Returns!E17)*(1+Returns!E18)*(1+Returns!E19)-1 -> 0.0012388162 | F22: =(1+Returns!F14)*(1+Returns!F15)*(1+Returns!F16)*(1+Returns!F17)*(1+Returns!F18)*(1+Returns!F19)-1 -> 0.31237323 | G22: =(1+Returns!G14)*(1+Returns!G15)*(1+Returns!G16)*(1+Returns!G17)*(1+Returns!G18)*(1+Returns!G19)-1 -> -0.025423729 | H22: =(1+Returns!H14)*(1+Returns!H15)*(1+Returns!H16)*(1+Returns!H17)*(1+Returns!H18)*(1+Returns!H19)-1 -> -0.024141133 | I22: =(1+Returns!I14)*(1+Returns!I15)*(1+Returns!I16)*(1+Returns!I17)*(1+Returns!I18)*(1+Returns!I19)-1 -> 0.3 | J22: =(1+Returns!J14)*(1+Returns!J15)*(1+Returns!J16)*(1+Returns!J17)*(1+Returns!J18)*(1+Returns!J19)-1 -> 0.15136467
... A124: 120 | B124: =Returns!A121 -> 45627 | C124: =(1+Returns!C116)*(1+Returns!C117)*(1+Returns!C118)*(1+Returns!C119)*(1+Returns!C120)*(1+Returns!C121)-1 -> 0.012426778 | D124: =(1+Returns!D116)*(1+Returns!D117)*(1+Returns!D118)*(1+Returns!D119)*(1+Returns!D120)*(1+Returns!D121)-1 -> 0.22991206 | E124: =(1+Returns!E116)*(1+Returns!E117)*(1+Returns!E118)*(1+Returns!E119)*(1+Returns!E120)*(1+Returns!E121)-1 -> 0.23920705 | F124: =(1+Returns!F116)*(1+Returns!F117)*(1+Returns!F118)*(1+Returns!F119)*(1+Returns!F120)*(1+Returns!F121)-1 -> 0.21852889 | G124: =(1+Returns!G116)*(1+Returns!G117)*(1+Returns!G118)*(1+Returns!G119)*(1+Returns!G120)*(1+Returns!G121)-1 -> 1.2446078 | H124: =(1+Returns!H116)*(1+Returns!H117)*(1+Returns!H118)*(1+Returns!H119)*(1+Returns!H120)*(1+Returns!H121)-1 -> 0.34021187 | I124: =(1+Returns!I116)*(1+Returns!I117)*(1+Returns!I118)*(1+Returns!I119)*(1+Returns!I120)*(1+Returns!I121)-1 -> 1.3960643 | J124: =(1+Returns!J116)*(1+Returns!J117)*(1+Returns!J118)*(1+Returns!J119)*(1+Returns!J120)*(1+Returns!J121)-1 -> 0.46761373

Sheet Rankings
A1: Momentum Rank (1 = strongest 6-month trailing return)
A4: Month (i) | B4: Date | C4: OGDC | D4: MEBL | E4: EFERT | F4: MCB | G4: LUCK | H4: FFC | I4: SAZEW | J4: MARI
A5: 1 | B5: =Momentum_Signal!B5 -> 42005
A6: 2 | B6: =Momentum_Signal!B6 -> 42036
A7: 3 | B7: =Momentum_Signal!B7 -> 42064
A8: 4 | B8: =Momentum_Signal!B8 -> 42095
A9: 5 | B9: =Momentum_Signal!B9 -> 42125
A10: 6 | B10: =Momentum_Signal!B10 -> 42156
A11: 7 | B11: =Momentum_Signal!B11 -> 42186 | C11: =RANK(Momentum_Signal!C11,Momentum_Signal!$C11:$J11,0) -> 6 | D11: =RANK(Momentum_Signal!D11,Momentum_Signal!$C11:$J11,0) -> 3 | E11: =RANK(Momentum_Signal!E11,Momentum_Signal!$C11:$J11,0) -> 7 | F11: =RANK(Momentum_Signal!F11,Momentum_Signal!$C11:$J11,0) -> 4 | G11: =RANK(Momentum_Signal!G11,Momentum_Signal!$C11:$J11,0) -> 2 | H11: =RANK(Momentum_Signal!H11,Momentum_Signal!$C11:$J11,0) -> 1 | I11: =RANK(Momentum_Signal!I11,Momentum_Signal!$C11:$J11,0) -> 8 | J11: =RANK(Momentum_Signal!J11,Momentum_Signal!$C11:$J11,0) -> 5
A12: 8 | B12: =Momentum_Signal!B12 -> 42217 | C12: =RANK(Momentum_Signal!C12,Momentum_Signal!$C12:$J12,0) -> 4 | D12: =RANK(Momentum_Signal!D12,Momentum_Signal!$C12:$J12,0) -> 1 | E12: =RANK(Momentum_Signal!E12,Momentum_Signal!$C12:$J12,0) -> 7 | F12: =RANK(Momentum_Signal!F12,Momentum_Signal!$C12:$J12,0) -> 2 | G12: =RANK(Momentum_Signal!G12,Momentum_Signal!$C12:$J12,0) -> 5 | H12: =RANK(Momentum_Signal!H12,Momentum_Signal!$C12:$J12,0) -> 6 | I12: =RANK(Momentum_Signal!I12,Momentum_Signal!$C12:$J12,0) -> 8 | J12: =RANK(Momentum_Signal!J12,Momentum_Signal!$C12:$J12,0) -> 3
A13: 9 | B13: =Momentum_Signal!B13 -> 42248 | C13: =RANK(Momentum_Signal!C13,Momentum_Signal!$C13:$J13,0) -> 3 | D13: =RANK(Momentum_Signal!D13,Momentum_Signal!$C13:$J13,0) -> 2 | E13: =RANK(Momentum_Signal!E13,Momentum_Signal!$C13:$J13,0) -> 6 | F13: =RANK(Momentum_Signal!F13,Momentum_Signal!$C13:$J13,0) -> 1 | G13: =RANK(Momentum_Signal!G13,Momentum_Signal!$C13:$J13,0) -> 5 | H13: =RANK(Momentum_Signal!H13,Momentum_Signal!$C13:$J13,0) -> 7 | I13: =RANK(Momentum_Signal!I13,Momentum_Signal!$C13:$J13,0) -> 8 | J13: =RANK(Momentum_Signal!J13,Momentum_Signal!$C13:$J13,0) -> 4
A14: 10 | B14: =Momentum_Signal!B14 -> 42278 | C14: =RANK(Momentum_Signal!C14,Momentum_Signal!$C14:$J14,0) -> 2 | D14: =RANK(Momentum_Signal!D14,Momentum_Signal!$C14:$J14,0) -> 3 | E14: =RANK(Momentum_Signal!E14,Momentum_Signal!$C14:$J14,0) -> 5 | F14: =RANK(Momentum_Signal!F14,Momentum_Signal!$C14:$J14,0) -> 1 | G14: =RANK(Momentum_Signal!G14,Momentum_Signal!$C14:$J14,0) -> 6 | H14: =RANK(Momentum_Signal!H14,Momentum_Signal!$C14:$J14,0) -> 7 | I14: =RANK(Momentum_Signal!I14,Momentum_Signal!$C14:$J14,0) -> 8 | J14: =RANK(Momentum_Signal!J14,Momentum_Signal!$C14:$J14,0) -> 4
A15: 11 | B15: =Momentum_Signal!B15 -> 42309 | C15: =RANK(Momentum_Signal!C15,Momentum_Signal!$C15:$J15,0) -> 1 | D15: =RANK(Momentum_Signal!D15,Momentum_Signal!$C15:$J15,0) -> 5 | E15: =RANK(Momentum_Signal!E15,Momentum_Signal!$C15:$J15,0) -> 8 | F15: =RANK(Momentum_Signal!F15,Momentum_Signal!$C15:$J15,0) -> 3 | G15: =RANK(Momentum_Signal!G15,Momentum_Signal!$C15:$J15,0) -> 6 | H15: =RANK(Momentum_Signal!H15,Momentum_Signal!$C15:$J15,0) -> 7 | I15: =RANK(Momentum_Signal!I15,Momentum_Signal!$C15:$J15,0) -> 2 | J15: =RANK(Momentum_Signal!J15,Momentum_Signal!$C15:$J15,0) -> 4
A16: 12 | B16: =Momentum_Signal!B16 -> 42339 | C16: =RANK(Momentum_Signal!C16,Momentum_Signal!$C16:$J16,0) -> 2 | D16: =RANK(Momentum_Signal!D16,Momentum_Signal!$C16:$J16,0) -> 5 | E16: =RANK(Momentum_Signal!E16,Momentum_Signal!$C16:$J16,0) -> 6 | F16: =RANK(Momentum_Signal!F16,Momentum_Signal!$C16:$J16,0) -> 4 | G16: =RANK(Momentum_Signal!G16,Momentum_Signal!$C16:$J16,0) -> 8 | H16: =RANK(Momentum_Signal!H16,Momentum_Signal!$C16:$J16,0) -> 7 | I16: =RANK(Momentum_Signal!I16,Momentum_Signal!$C16:$J16,0) -> 1 | J16: =RANK(Momentum_Signal!J16,Momentum_Signal!$C16:$J16,0) -> 3
A17: 13 | B17: =Momentum_Signal!B17 -> 42370 | C17: =RANK(Momentum_Signal!C17,Momentum_Signal!$C17:$J17,0) -> 2 | D17: =RANK(Momentum_Signal!D17,Momentum_Signal!$C17:$J17,0) -> 5 | E17: =RANK(Momentum_Signal!E17,Momentum_Signal!$C17:$J17,0) -> 8 | F17: =RANK(Momentum_Signal!F17,Momentum_Signal!$C17:$J17,0) -> 4 | G17: =RANK(Momentum_Signal!G17,Momentum_Signal!$C17:$J17,0) -> 6 | H17: =RANK(Momentum_Signal!H17,Momentum_Signal!$C17:$J17,0) -> 7 | I17: =RANK(Momentum_Signal!I17,Momentum_Signal!$C17:$J17,0) -> 1 | J17: =RANK(Momentum_Signal!J17,Momentum_Signal!$C17:$J17,0) -> 3
A18: 14 | B18: =Momentum_Signal!B18 -> 42401 | C18: =RANK(Momentum_Signal!C18,Momentum_Signal!$C18:$J18,0) -> 4 | D18: =RANK(Momentum_Signal!D18,Momentum_Signal!$C18:$J18,0) -> 5 | E18: =RANK(Momentum_Signal!E18,Momentum_Signal!$C18:$J18,0) -> 7 | F18: =RANK(Momentum_Signal!F18,Momentum_Signal!$C18:$J18,0) -> 2 | G18: =RANK(Momentum_Signal!G18,Momentum_Signal!$C18:$J18,0) -> 6 | H18: =RANK(Momentum_Signal!H18,Momentum_Signal!$C18:$J18,0) -> 8 | I18: =RANK(Momentum_Signal!I18,Momentum_Signal!$C18:$J18,0) -> 1 | J18: =RANK(Momentum_Signal!J18,Momentum_Signal!$C18:$J18,0) -> 3
A19: 15 | B19: =Momentum_Signal!B19 -> 42430 | C19: =RANK(Momentum_Signal!C19,Momentum_Signal!$C19:$J19,0) -> 7 | D19: =RANK(Momentum_Signal!D19,Momentum_Signal!$C19:$J19,0) -> 8 | E19: =RANK(Momentum_Signal!E19,Momentum_Signal!$C19:$J19,0) -> 5 | F19: =RANK(Momentum_Signal!F19,Momentum_Signal!$C19:$J19,0) -> 3 | G19: =RANK(Momentum_Signal!G19,Momentum_Signal!$C19:$J19,0) -> 6 | H19: =RANK(Momentum_Signal!H19,Momentum_Signal!$C19:$J19,0) -> 4 | I19: =RANK(Momentum_Signal!I19,Momentum_Signal!$C19:$J19,0) -> 1 | J19: =RANK(Momentum_Signal!J19,Momentum_Signal!$C19:$J19,0) -> 2
A20: 16 | B20: =Momentum_Signal!B20 -> 42461 | C20: =RANK(Momentum_Signal!C20,Momentum_Signal!$C20:$J20,0) -> 5 | D20: =RANK(Momentum_Signal!D20,Momentum_Signal!$C20:$J20,0) -> 8 | E20: =RANK(Momentum_Signal!E20,Momentum_Signal!$C20:$J20,0) -> 6 | F20: =RANK(Momentum_Signal!F20,Momentum_Signal!$C20:$J20,0) -> 2 | G20: =RANK(Momentum_Signal!G20,Momentum_Signal!$C20:$J20,0) -> 7 | H20: =RANK(Momentum_Signal!H20,Momentum_Signal!$C20:$J20,0) -> 3 | I20: =RANK(Momentum_Signal!I20,Momentum_Signal!$C20:$J20,0) -> 1 | J20: =RANK(Momentum_Signal!J20,Momentum_Signal!$C20:$J20,0) -> 4
A21: 17 | B21: =Momentum_Signal!B21 -> 42491 | C21: =RANK(Momentum_Signal!C21,Momentum_Signal!$C21:$J21,0) -> 7 | D21: =RANK(Momentum_Signal!D21,Momentum_Signal!$C21:$J21,0) -> 8 | E21: =RANK(Momentum_Signal!E21,Momentum_Signal!$C21:$J21,0) -> 5 | F21: =RANK(Momentum_Signal!F21,Momentum_Signal!$C21:$J21,0) -> 2 | G21: =RANK(Momentum_Signal!G21,Momentum_Signal!$C21:$J21,0) -> 6 | H21: =RANK(Momentum_Signal!H21,Momentum_Signal!$C21:$J21,0) -> 4 | I21: =RANK(Momentum_Signal!I21,Momentum_Signal!$C21:$J21,0) -> 1 | J21: =RANK(Momentum_Signal!J21,Momentum_Signal!$C21:$J21,0) -> 3
A22: 18 | B22: =Momentum_Signal!B22 -> 42522 | C22: =RANK(Momentum_Signal!C22,Momentum_Signal!$C22:$J22,0) -> 7 | D22: =RANK(Momentum_Signal!D22,Momentum_Signal!$C22:$J22,0) -> 8 | E22: =RANK(Momentum_Signal!E22,Momentum_Signal!$C22:$J22,0) -> 4 | F22: =RANK(Momentum_Signal!F22,Momentum_Signal!$C22:$J22,0) -> 1 | G22: =RANK(Momentum_Signal!G22,Momentum_Signal!$C22:$J22,0) -> 6 | H22: =RANK(Momentum_Signal!H22,Momentum_Signal!$C22:$J22,0) -> 5 | I22: =RANK(Momentum_Signal!I22,Momentum_Signal!$C22:$J22,0) -> 2 | J22: =RANK(Momentum_Signal!J22,Momentum_Signal!$C22:$J22,0) -> 3
... A124: 120 | B124: =Momentum_Signal!B124 -> 45627 | C124: =RANK(Momentum_Signal!C124,Momentum_Signal!$C124:$J124,0) -> 8 | D124: =RANK(Momentum_Signal!D124,Momentum_Signal!$C124:$J124,0) -> 6 | E124: =RANK(Momentum_Signal!E124,Momentum_Signal!$C124:$J124,0) -> 5 | F124: =RANK(Momentum_Signal!F124,Momentum_Signal!$C124:$J124,0) -> 7 | G124: =RANK(Momentum_Signal!G124,Momentum_Signal!$C124:$J124,0) -> 2 | H124: =RANK(Momentum_Signal!H124,Momentum_Signal!$C124:$J124,0) -> 4 | I124: =RANK(Momentum_Signal!I124,Momentum_Signal!$C124:$J124,0) -> 1 | J124: =RANK(Momentum_Signal!J124,Momentum_Signal!$C124:$J124,0) -> 3

Sheet S_Top2_Annual
A1: Scenario: Top 2 stocks, Annual rebalancing (hold 12 months)
A2: Holdings flag in each row = lookup of Rankings at the governing formation-month (decision row), held constant until next rebalance. Decision i -> holding starts month i+1.
A4: Month (j) | B4: Date | C4: OGDC | D4: MEBL | E4: EFERT | F4: MCB | G4: LUCK | H4: FFC | I4: SAZEW | J4: MARI | K4: Held N | L4: Gross Return | M4: Txn Cost | N4: CGT | O4: Net Return | P4: Growth of Rs.1 | Q4: Running Max | R4: Drawdown | S4: Excess Return
A5: 8 | B5: =Returns!A9 -> 42217 | C5: =IF(Rankings!C11<=2,1,0) -> 0 | D5: =IF(Rankings!D11<=2,1,0) -> 0 | E5: =IF(Rankings!E11<=2,1,0) -> 0 | F5: =IF(Rankings!F11<=2,1,0) -> 0 | G5: =IF(Rankings!G11<=2,1,0) -> 1 | H5: =IF(Rankings!H11<=2,1,0) -> 1 | I5: =IF(Rankings!I11<=2,1,0) -> 0 | J5: =IF(Rankings!J11<=2,1,0) -> 0 | K5: =SUM(C5:J5) -> 2 | L5: =SUMPRODUCT(C5:J5,Returns!B9:I9)/K5 -> -0.056681129 | M5: =-2*Assumptions!$B$13 -> -0.007 | N5: 0 | O5: =L5+M5+N5 -> -0.063681129 | P5: =1*(1+O5) -> 0.93631887 | Q5: =MAX($P$5:P5) -> 0.93631887 | R5: =P5/Q5-1 -> 0 | S5: =O5-Benchmark_RF!D5 -> -0.06928106
A6: 9 | B6: =Returns!A10 -> 42248 | C6: =IF(Rankings!C11<=2,1,0) -> 0 | D6: =IF(Rankings!D11<=2,1,0) -> 0 | E6: =IF(Rankings!E11<=2,1,0) -> 0 | F6: =IF(Rankings!F11<=2,1,0) -> 0 | G6: =IF(Rankings!G11<=2,1,0) -> 1 | H6: =IF(Rankings!H11<=2,1,0) -> 1 | I6: =IF(Rankings!I11<=2,1,0) -> 0 | J6: =IF(Rankings!J11<=2,1,0) -> 0 | K6: =SUM(C6:J6) -> 2 | L6: =SUMPRODUCT(C6:J6,Returns!B10:I10)/K6 -> -0.050873779 | M6: 0 | N6: 0 | O6: =L6+M6+N6 -> -0.050873779 | P6: =P5*(1+O6) -> 0.88868479 | Q6: =MAX($P$5:P6) -> 0.93631887 | R6: =P6/Q6-1 -> -0.050873779 | S6: =O6-Benchmark_RF!D6 -> -0.056108962
A7: 10 | B7: =Returns!A11 -> 42278 | C7: =IF(Rankings!C11<=2,1,0) -> 0 | D7: =IF(Rankings!D11<=2,1,0) -> 0 | E7: =IF(Rankings!E11<=2,1,0) -> 0 | F7: =IF(Rankings!F11<=2,1,0) -> 0 | G7: =IF(Rankings!G11<=2,1,0) -> 1 | H7: =IF(Rankings!H11<=2,1,0) -> 1 | I7: =IF(Rankings!I11<=2,1,0) -> 0 | J7: =IF(Rankings!J11<=2,1,0) -> 0 | K7: =SUM(C7:J7) -> 2 | L7: =SUMPRODUCT(C7:J7,Returns!B11:I11)/K7 -> 0.01976487 | M7: 0 | N7: 0 | O7: =L7+M7+N7 -> 0.01976487 | P7: =P6*(1+O7) -> 0.90624953 | Q7: =MAX($P$5:P7) -> 0.93631887 | R7: =P7/Q7-1 -> -0.032114423 | S7: =O7-Benchmark_RF!D7 -> 0.014657635
A8: 11 | B8: =Returns!A12 -> 42309 | C8: =IF(Rankings!C11<=2,1,0) -> 0 | D8: =IF(Rankings!D11<=2,1,0) -> 0 | E8: =IF(Rankings!E11<=2,1,0) -> 0 | F8: =IF(Rankings!F11<=2,1,0) -> 0 | G8: =IF(Rankings!G11<=2,1,0) -> 1 | H8: =IF(Rankings!H11<=2,1,0) -> 1 | I8: =IF(Rankings!I11<=2,1,0) -> 0 | J8: =IF(Rankings!J11<=2,1,0) -> 0 | K8: =SUM(C8:J8) -> 2 | L8: =SUMPRODUCT(C8:J8,Returns!B12:I12)/K8 -> -0.076639329 | M8: 0 | N8: 0 | O8: =L8+M8+N8 -> -0.076639329 | P8: =P7*(1+O8) -> 0.83679517 | Q8: =MAX($P$5:P8) -> 0.93631887 | R8: =P8/Q8-1 -> -0.10629252 | S8: =O8-Benchmark_RF!D8 -> -0.081798001
A9: 12 | B9: =Returns!A13 -> 42339 | C9: =IF(Rankings!C11<=2,1,0) -> 0 | D9: =IF(Rankings!D11<=2,1,0) -> 0 | E9: =IF(Rankings!E11<=2,1,0) -> 0 | F9: =IF(Rankings!F11<=2,1,0) -> 0 | G9: =IF(Rankings!G11<=2,1,0) -> 1 | H9: =IF(Rankings!H11<=2,1,0) -> 1 | I9: =IF(Rankings!I11<=2,1,0) -> 0 | J9: =IF(Rankings!J11<=2,1,0) -> 0 | K9: =SUM(C9:J9) -> 2 | L9: =SUMPRODUCT(C9:J9,Returns!B13:I13)/K9 -> 0.0036517747 | M9: 0 | N9: 0 | O9: =L9+M9+N9 -> 0.0036517747 | P9: =P8*(1+O9) -> 0.83985096 | Q9: =MAX($P$5:P9) -> 0.93631887 | R9: =P9/Q9-1 -> -0.10302891 | S9: =O9-Benchmark_RF!D9 -> -0.0014819305
A10: 13 | B10: =Returns!A14 -> 42370 | C10: =IF(Rankings!C11<=2,1,0) -> 0 | D10: =IF(Rankings!D11<=2,1,0) -> 0 | E10: =IF(Rankings!E11<=2,1,0) -> 0 | F10: =IF(Rankings!F11<=2,1,0) -> 0 | G10: =IF(Rankings!G11<=2,1,0) -> 1 | H10: =IF(Rankings!H11<=2,1,0) -> 1 | I10: =IF(Rankings!I11<=2,1,0) -> 0 | J10: =IF(Rankings!J11<=2,1,0) -> 0 | K10: =SUM(C10:J10) -> 2 | L10: =SUMPRODUCT(C10:J10,Returns!B14:I14)/K10 -> -0.039326761 | M10: 0 | N10: 0 | O10: =L10+M10+N10 -> -0.039326761 | P10: =P9*(1+O10) -> 0.80682234 | Q10: =MAX($P$5:P10) -> 0.93631887 | R10: =P10/Q10-1 -> -0.13830387 | S10: =O10-Benchmark_RF!D10 -> -0.044321964
A11: 14 | B11: =Returns!A15 -> 42401 | C11: =IF(Rankings!C11<=2,1,0) -> 0 | D11: =IF(Rankings!D11<=2,1,0) -> 0 | E11: =IF(Rankings!E11<=2,1,0) -> 0 | F11: =IF(Rankings!F11<=2,1,0) -> 0 | G11: =IF(Rankings!G11<=2,1,0) -> 1 | H11: =IF(Rankings!H11<=2,1,0) -> 1 | I11: =IF(Rankings!I11<=2,1,0) -> 0 | J11: =IF(Rankings!J11<=2,1,0) -> 0 | K11: =SUM(C11:J11) -> 2 | L11: =SUMPRODUCT(C11:J11,Returns!B15:I15)/K11 -> -0.0034381328 | M11: 0 | N11: 0 | O11: =L11+M11+N11 -> -0.0034381328 | P11: =P10*(1+O11) -> 0.80404838 | Q11: =MAX($P$5:P11) -> 0.93631887 | R11: =P11/Q11-1 -> -0.1412665 | S11: =O11-Benchmark_RF!D11 -> -0.0084746639
A12: 15 | B12: =Returns!A16 -> 42430 | C12: =IF(Rankings!C11<=2,1,0) -> 0 | D12: =IF(Rankings!D11<=2,1,0) -> 0 | E12: =IF(Rankings!E11<=2,1,0) -> 0 | F12: =IF(Rankings!F11<=2,1,0) -> 0 | G12: =IF(Rankings!G11<=2,1,0) -> 1 | H12: =IF(Rankings!H11<=2,1,0) -> 1 | I12: =IF(Rankings!I11<=2,1,0) -> 0 | J12: =IF(Rankings!J11<=2,1,0) -> 0 | K12: =SUM(C12:J12) -> 2 | L12: =SUMPRODUCT(C12:J12,Returns!B16:I16)/K12 -> 0.036975958 | M12: 0 | N12: 0 | O12: =L12+M12+N12 -> 0.036975958 | P12: =P11*(1+O12) -> 0.83377884 | Q12: =MAX($P$5:P12) -> 0.93631887 | R12: =P12/Q12-1 -> -0.10951401 | S12: =O12-Benchmark_RF!D12 -> 0.031974445
A13: 16 | B13: =Returns!A17 -> 42461 | C13: =IF(Rankings!C11<=2,1,0) -> 0 | D13: =IF(Rankings!D11<=2,1,0) -> 0 | E13: =IF(Rankings!E11<=2,1,0) -> 0 | F13: =IF(Rankings!F11<=2,1,0) -> 0 | G13: =IF(Rankings!G11<=2,1,0) -> 1 | H13: =IF(Rankings!H11<=2,1,0) -> 1 | I13: =IF(Rankings!I11<=2,1,0) -> 0 | J13: =IF(Rankings!J11<=2,1,0) -> 0 | K13: =SUM(C13:J13) -> 2 | L13: =SUMPRODUCT(C13:J13,Returns!B17:I17)/K13 -> 0.01748769 | M13: 0 | N13: 0 | O13: =L13+M13+N13 -> 0.01748769 | P13: =P12*(1+O13) -> 0.84835971 | Q13: =MAX($P$5:P13) -> 0.93631887 | R13: =P13/Q13-1 -> -0.093941462 | S13: =O13-Benchmark_RF!D13 -> 0.012486176
A14: 17 | B14: =Returns!A18 -> 42491 | C14: =IF(Rankings!C11<=2,1,0) -> 0 | D14: =IF(Rankings!D11<=2,1,0) -> 0 | E14: =IF(Rankings!E11<=2,1,0) -> 0 | F14: =IF(Rankings!F11<=2,1,0) -> 0 | G14: =IF(Rankings!G11<=2,1,0) -> 1 | H14: =IF(Rankings!H11<=2,1,0) -> 1 | I14: =IF(Rankings!I11<=2,1,0) -> 0 | J14: =IF(Rankings!J11<=2,1,0) -> 0 | K14: =SUM(C14:J14) -> 2 | L14: =SUMPRODUCT(C14:J14,Returns!B18:I18)/K14 -> 0.069048945 | M14: 0 | N14: 0 | O14: =L14+M14+N14 -> 0.069048945 | P14: =P13*(1+O14) -> 0.90693805 | Q14: =MAX($P$5:P14) -> 0.93631887 | R14: =P14/Q14-1 -> -0.031379076 | S14: =O14-Benchmark_RF!D14 -> 0.06419127
A15: 18 | B15: =Returns!A19 -> 42522 | C15: =IF(Rankings!C11<=2,1,0) -> 0 | D15: =IF(Rankings!D11<=2,1,0) -> 0 | E15: =IF(Rankings!E11<=2,1,0) -> 0 | F15: =IF(Rankings!F11<=2,1,0) -> 0 | G15: =IF(Rankings!G11<=2,1,0) -> 1 | H15: =IF(Rankings!H11<=2,1,0) -> 1 | I15: =IF(Rankings!I11<=2,1,0) -> 0 | J15: =IF(Rankings!J11<=2,1,0) -> 0 | K15: =SUM(C15:J15) -> 2 | L15: =SUMPRODUCT(C15:J15,Returns!B19:I19)/K15 -> 0.0501073 | M15: 0 | N15: 0 | O15: =L15+M15+N15 -> 0.0501073 | P15: =P14*(1+O15) -> 0.95238227 | Q15: =MAX($P$5:P15) -> 0.95238227 | R15: =P15/Q15-1 -> 0 | S15: =O15-Benchmark_RF!D15 -> 0.045318941
A16: 19 | B16: =Returns!A20 -> 42552 | C16: =IF(Rankings!C11<=2,1,0) -> 0 | D16: =IF(Rankings!D11<=2,1,0) -> 0 | E16: =IF(Rankings!E11<=2,1,0) -> 0 | F16: =IF(Rankings!F11<=2,1,0) -> 0 | G16: =IF(Rankings!G11<=2,1,0) -> 1 | H16: =IF(Rankings!H11<=2,1,0) -> 1 | I16: =IF(Rankings!I11<=2,1,0) -> 0 | J16: =IF(Rankings!J11<=2,1,0) -> 0 | K16: =SUM(C16:J16) -> 2 | L16: =SUMPRODUCT(C16:J16,Returns!B20:I20)/K16 -> 0.067811975 | M16: 0 | N16: 0 | O16: =L16+M16+N16 -> 0.067811975 | P16: =P15*(1+O16) -> 1.0169652 | Q16: =MAX($P$5:P16) -> 1.0169652 | R16: =P16/Q16-1 -> 0 | S16: =O16-Benchmark_RF!D16 -> 0.06311261
A17: 20 | B17: =Returns!A21 -> 42583 | C17: =IF(Rankings!C23<=2,1,0) -> 0 | D17: =IF(Rankings!D23<=2,1,0) -> 0 | E17: =IF(Rankings!E23<=2,1,0) -> 0 | F17: =IF(Rankings!F23<=2,1,0) -> 1 | G17: =IF(Rankings!G23<=2,1,0) -> 0 | H17: =IF(Rankings!H23<=2,1,0) -> 0 | I17: =IF(Rankings!I23<=2,1,0) -> 1 | J17: =IF(Rankings!J23<=2,1,0) -> 0 | K17: =SUM(C17:J17) -> 2 | L17: =SUMPRODUCT(C17:J17,Returns!B21:I21)/K17 -> 0.042663683 | M17: =-2*Assumptions!$B$13 -> -0.007 | N17: =-Assumptions!$B$16*MAX(0,(1+O5)*(1+O6)*(1+O7)*(1+O8)*(1+O9)*(1+O10)*(1+O11)*(1+O12)*(1+O13)*(1+O14)*(1+O15)*(1+O16)-1) -> -0.0025447783 | O17: =L17+M17+N17 -> 0.033118905 | P17: =P16*(1+O17) -> 1.050646 | Q17: =MAX($P$5:P17) -> 1.050646 | R17: =P17/Q17-1 -> 0 | S17: =O17-Benchmark_RF!D17 -> 0.02836202
A18: 21 | B18: =Returns!A22 -> 42614 | C18: =IF(Rankings!C23<=2,1,0) -> 0 | D18: =IF(Rankings!D23<=2,1,0) -> 0 | E18: =IF(Rankings!E23<=2,1,0) -> 0 | F18: =IF(Rankings!F23<=2,1,0) -> 1 | G18: =IF(Rankings!G23<=2,1,0) -> 0 | H18: =IF(Rankings!H23<=2,1,0) -> 0 | I18: =IF(Rankings!I23<=2,1,0) -> 1 | J18: =IF(Rankings!J23<=2,1,0) -> 0 | K18: =SUM(C18:J18) -> 2 | L18: =SUMPRODUCT(C18:J18,Returns!B22:I22)/K18 -> 0.30210015 | M18: 0 | N18: 0 | O18: =L18+M18+N18 -> 0.30210015 | P18: =P17*(1+O18) -> 1.3680463 | Q18: =MAX($P$5:P18) -> 1.3680463 | R18: =P18/Q18-1 -> 0 | S18: =O18-Benchmark_RF!D18 -> 0.29734326
A19: 22 | B19: =Returns!A23 -> 42644 | C19: =IF(Rankings!C23<=2,1,0) -> 0 | D19: =IF(Rankings!D23<=2,1,0) -> 0 | E19: =IF(Rankings!E23<=2,1,0) -> 0 | F19: =IF(Rankings!F23<=2,1,0) -> 1 | G19: =IF(Rankings!G23<=2,1,0) -> 0 | H19: =IF(Rankings!H23<=2,1,0) -> 0 | I19: =IF(Rankings!I23<=2,1,0) -> 1 | J19: =IF(Rankings!J23<=2,1,0) -> 0 | K19: =SUM(C19:J19) -> 2 | L19: =SUMPRODUCT(C19:J19,Returns!B23:I23)/K19 -> 0.10422243 | M19: 0 | N19: 0 | O19: =L19+M19+N19 -> 0.10422243 | P19: =P18*(1+O19) -> 1.5106274 | Q19: =MAX($P$5:P19) -> 1.5106274 | R19: =P19/Q19-1 -> 0 | S19: =O19-Benchmark_RF!D19 -> 0.099449724
A20: 23 | B20: =Returns!A24 -> 42675 | C20: =IF(Rankings!C23<=2,1,0) -> 0 | D20: =IF(Rankings!D23<=2,1,0) -> 0 | E20: =IF(Rankings!E23<=2,1,0) -> 0 | F20: =IF(Rankings!F23<=2,1,0) -> 1 | G20: =IF(Rankings!G23<=2,1,0) -> 0 | H20: =IF(Rankings!H23<=2,1,0) -> 0 | I20: =IF(Rankings!I23<=2,1,0) -> 1 | J20: =IF(Rankings!J23<=2,1,0) -> 0 | K20: =SUM(C20:J20) -> 2 | L20: =SUMPRODUCT(C20:J20,Returns!B24:I24)/K20 -> 0.22200623 | M20: 0 | N20: 0 | O20: =L20+M20+N20 -> 0.22200623 | P20: =P19*(1+O20) -> 1.845996 | Q20: =MAX($P$5:P20) -> 1.845996 | R20: =P20/Q20-1 -> 0 | S20: =O20-Benchmark_RF!D20 -> 0.21717819
A21: 24 | B21: =Returns!A25 -> 42705 | C21: =IF(Rankings!C23<=2,1,0) -> 0 | D21: =IF(Rankings!D23<=2,1,0) -> 0 | E21: =IF(Rankings!E23<=2,1,0) -> 0 | F21: =IF(Rankings!F23<=2,1,0) -> 1 | G21: =IF(Rankings!G23<=2,1,0) -> 0 | H21: =IF(Rankings!H23<=2,1,0) -> 0 | I21: =IF(Rankings!I23<=2,1,0) -> 1 | J21: =IF(Rankings!J23<=2,1,0) -> 0 | K21: =SUM(C21:J21) -> 2 | L21: =SUMPRODUCT(C21:J21,Returns!B25:I25)/K21 -> 0.0085534527 | M21: 0 | N21: 0 | O21: =L21+M21+N21 -> 0.0085534527 | P21: =P20*(1+O21) -> 1.8617857 | Q21: =MAX($P$5:P21) -> 1.8617857 | R21: =P21/Q21-1 -> 0 | S21: =O21-Benchmark_RF!D21 -> 0.003713635
A22: 25 | B22: =Returns!A26 -> 42736 | C22: =IF(Rankings!C23<=2,1,0) -> 0 | D22: =IF(Rankings!D23<=2,1,0) -> 0 | E22: =IF(Rankings!E23<=2,1,0) -> 0 | F22: =IF(Rankings!F23<=2,1,0) -> 1 | G22: =IF(Rankings!G23<=2,1,0) -> 0 | H22: =IF(Rankings!H23<=2,1,0) -> 0 | I22: =IF(Rankings!I23<=2,1,0) -> 1 | J22: =IF(Rankings!J23<=2,1,0) -> 0 | K22: =SUM(C22:J22) -> 2 | L22: =SUMPRODUCT(C22:J22,Returns!B26:I26)/K22 -> -0.0048449545 | M22: 0 | N22: 0 | O22: =L22+M22+N22 -> -0.0048449545 | P22: =P21*(1+O22) -> 1.8527654 | Q22: =MAX($P$5:P22) -> 1.8617857 | R22: =P22/Q22-1 -> -0.0048449545 | S22: =O22-Benchmark_RF!D22 -> -0.0096193177
A23: 26 | B23: =Returns!A27 -> 42767 | C23: =IF(Rankings!C23<=2,1,0) -> 0 | D23: =IF(Rankings!D23<=2,1,0) -> 0 | E23: =IF(Rankings!E23<=2,1,0) -> 0 | F23: =IF(Rankings!F23<=2,1,0) -> 1 | G23: =IF(Rankings!G23<=2,1,0) -> 0 | H23: =IF(Rankings!H23<=2,1,0) -> 0 | I23: =IF(Rankings!I23<=2,1,0) -> 1 | J23: =IF(Rankings!J23<=2,1,0) -> 0 | K23: =SUM(C23:J23) -> 2 | L23: =SUMPRODUCT(C23:J23,Returns!B27:I27)/K23 -> -0.046817195 | M23: 0 | N23: 0 | O23: =L23+M23+N23 -> -0.046817195 | P23: =P22*(1+O23) -> 1.7660241 | Q23: =MAX($P$5:P23) -> 1.8617857 | R23: =P23/Q23-1 -> -0.051435322 | S23: =O23-Benchmark_RF!D23 -> -0.051638677
A24: 27 | B24: =Returns!A28 -> 42795 | C24: =IF(Rankings!C23<=2,1,0) -> 0 | D24: =IF(Rankings!D23<=2,1,0) -> 0 | E24: =IF(Rankings!E23<=2,1,0) -> 0 | F24: =IF(Rankings!F23<=2,1,0) -> 1 | G24: =IF(Rankings!G23<=2,1,0) -> 0 | H24: =IF(Rankings!H23<=2,1,0) -> 0 | I24: =IF(Rankings!I23<=2,1,0) -> 1 | J24: =IF(Rankings!J23<=2,1,0) -> 0 | K24: =SUM(C24:J24) -> 2 | L24: =SUMPRODUCT(C24:J24,Returns!B28:I28)/K24 -> 0.015948658 | M24: 0 | N24: 0 | O24: =L24+M24+N24 -> 0.015948658 | P24: =P23*(1+O24) -> 1.7941899 | Q24: =MAX($P$5:P24) -> 1.8617857 | R24: =P24/Q24-1 -> -0.036306988 | S24: =O24-Benchmark_RF!D24 -> 0.011103388
A25: 28 | B25: =Returns!A29 -> 42826 | C25: =IF(Rankings!C23<=2,1,0) -> 0 | D25: =IF(Rankings!D23<=2,1,0) -> 0 | E25: =IF(Rankings!E23<=2,1,0) -> 0 | F25: =IF(Rankings!F23<=2,1,0) -> 1 | G25: =IF(Rankings!G23<=2,1,0) -> 0 | H25: =IF(Rankings!H23<=2,1,0) -> 0 | I25: =IF(Rankings!I23<=2,1,0) -> 1 | J25: =IF(Rankings!J23<=2,1,0) -> 0 | K25: =SUM(C25:J25) -> 2 | L25: =SUMPRODUCT(C25:J25,Returns!B29:I29)/K25 -> 0.11523305 | M25: 0 | N25: 0 | O25: =L25+M25+N25 -> 0.11523305 | P25: =P24*(1+O25) -> 2.0009398 | Q25: =MAX($P$5:P25) -> 2.0009398 | R25: =P25/Q25-1 -> 0 | S25: =O25-Benchmark_RF!D25 -> 0.11037727
A26: 29 | B26: =Returns!A30 -> 42856 | C26: =IF(Rankings!C23<=2,1,0) -> 0 | D26: =IF(Rankings!D23<=2,1,0) -> 0 | E26: =IF(Rankings!E23<=2,1,0) -> 0 | F26: =IF(Rankings!F23<=2,1,0) -> 1 | G26: =IF(Rankings!G23<=2,1,0) -> 0 | H26: =IF(Rankings!H23<=2,1,0) -> 0 | I26: =IF(Rankings!I23<=2,1,0) -> 1 | J26: =IF(Rankings!J23<=2,1,0) -> 0 | K26: =SUM(C26:J26) -> 2 | L26: =SUMPRODUCT(C26:J26,Returns!B30:I30)/K26 -> 0.37108568 | M26: 0 | N26: 0 | O26: =L26+M26+N26 -> 0.37108568 | P26: =P25*(1+O26) -> 2.74346 | Q26: =MAX($P$5:P26) -> 2.74346 | R26: =P26/Q26-1 -> 0 | S26: =O26-Benchmark_RF!D26 -> 0.36622991
A27: 30 | B27: =Returns!A31 -> 42887 | C27: =IF(Rankings!C23<=2,1,0) -> 0 | D27: =IF(Rankings!D23<=2,1,0) -> 0 | E27: =IF(Rankings!E23<=2,1,0) -> 0 | F27: =IF(Rankings!F23<=2,1,0) -> 1 | G27: =IF(Rankings!G23<=2,1,0) -> 0 | H27: =IF(Rankings!H23<=2,1,0) -> 0 | I27: =IF(Rankings!I23<=2,1,0) -> 1 | J27: =IF(Rankings!J23<=2,1,0) -> 0 | K27: =SUM(C27:J27) -> 2 | L27: =SUMPRODUCT(C27:J27,Returns!B31:I31)/K27 -> 0.14838463 | M27: 0 | N27: 0 | O27: =L27+M27+N27 -> 0.14838463 | P27: =P26*(1+O27) -> 3.1505472 | Q27: =MAX($P$5:P27) -> 3.1505472 | R27: =P27/Q27-1 -> 0 | S27: =O27-Benchmark_RF!D27 -> 0.14352419
A28: 31 | B28: =Returns!A32 -> 42917 | C28: =IF(Rankings!C23<=2,1,0) -> 0 | D28: =IF(Rankings!D23<=2,1,0) -> 0 | E28: =IF(Rankings!E23<=2,1,0) -> 0 | F28: =IF(Rankings!F23<=2,1,0) -> 1 | G28: =IF(Rankings!G23<=2,1,0) -> 0 | H28: =IF(Rankings!H23<=2,1,0) -> 0 | I28: =IF(Rankings!I23<=2,1,0) -> 1 | J28: =IF(Rankings!J23<=2,1,0) -> 0 | K28: =SUM(C28:J28) -> 2 | L28: =SUMPRODUCT(C28:J28,Returns!B32:I32)/K28 -> -0.097675356 | M28: 0 | N28: 0 | O28: =L28+M28+N28 -> -0.097675356 | P28: =P27*(1+O28) -> 2.8428164 | Q28: =MAX($P$5:P28) -> 3.1505472 | R28: =P28/Q28-1 -> -0.097675356 | S28: =O28-Benchmark_RF!D28 -> -0.10253572
A29: 32 | B29: =Returns!A33 -> 42948 | C29: =IF(Rankings!C35<=2,1,0) -> 0 | D29: =IF(Rankings!D35<=2,1,0) -> 0 | E29: =IF(Rankings!E35<=2,1,0) -> 0 | F29: =IF(Rankings!F35<=2,1,0) -> 0 | G29: =IF(Rankings!G35<=2,1,0) -> 0 | H29: =IF(Rankings!H35<=2,1,0) -> 1 | I29: =IF(Rankings!I35<=2,1,0) -> 1 | J29: =IF(Rankings!J35<=2,1,0) -> 0 | K29: =SUM(C29:J29) -> 2 | L29: =SUMPRODUCT(C29:J29,Returns!B33:I33)/K29 -> -0.21319483 | M29: =-2*Assumptions!$B$13 -> -0.007 | N29: =-Assumptions!$B$16*MAX(0,(1+O17)*(1+O18)*(1+O19)*(1+O20)*(1+O21)*(1+O22)*(1+O23)*(1+O24)*(1+O25)*(1+O26)*(1+O27)*(1+O28)-1) -> -0.26930881 | O29: =L29+M29+N29 -> -0.48950364 | P29: =P28*(1+O29) -> 1.4512474 | Q29: =MAX($P$5:P29) -> 3.1505472 | R29: =P29/Q29-1 -> -0.53936655 | S29: =O29-Benchmark_RF!D29 -> -0.49436345
A30: 33 | B30: =Returns!A34 -> 42979 | C30: =IF(Rankings!C35<=2,1,0) -> 0 | D30: =IF(Rankings!D35<=2,1,0) -> 0 | E30: =IF(Rankings!E35<=2,1,0) -> 0 | F30: =IF(Rankings!F35<=2,1,0) -> 0 | G30: =IF(Rankings!G35<=2,1,0) -> 0 | H30: =IF(Rankings!H35<=2,1,0) -> 1 | I30: =IF(Rankings!I35<=2,1,0) -> 1 | J30: =IF(Rankings!J35<=2,1,0) -> 0 | K30: =SUM(C30:J30) -> 2 | L30: =SUMPRODUCT(C30:J30,Returns!B34:I34)/K30 -> 0.10265278 | M30: 0 | N30: 0 | O30: =L30+M30+N30 -> 0.10265278 | P30: =P29*(1+O30) -> 1.600222 | Q30: =MAX($P$5:P30) -> 3.1505472 | R30: =P30/Q30-1 -> -0.49208125 | S30: =O30-Benchmark_RF!D30 -> 0.09779234
A31: 34 | B31: =Returns!A35 -> 43009 | C31: =IF(Rankings!C35<=2,1,0) -> 0 | D31: =IF(Rankings!D35<=2,1,0) -> 0 | E31: =IF(Rankings!E35<=2,1,0) -> 0 | F31: =IF(Rankings!F35<=2,1,0) -> 0 | G31: =IF(Rankings!G35<=2,1,0) -> 0 | H31: =IF(Rankings!H35<=2,1,0) -> 1 | I31: =IF(Rankings!I35<=2,1,0) -> 1 | J31: =IF(Rankings!J35<=2,1,0) -> 0 | K31: =SUM(C31:J31) -> 2 | L31: =SUMPRODUCT(C31:J31,Returns!B35:I35)/K31 -> -0.045651394 | M31: 0 | N31: 0 | O31: =L31+M31+N31 -> -0.045651394 | P31: =P30*(1+O31) -> 1.5271697 | Q31: =MAX($P$5:P31) -> 3.1505472 | R31: =P31/Q31-1 -> -0.51526845 | S31: =O31-Benchmark_RF!D31 -> -0.050511834
A32: 35 | B32: =Returns!A36 -> 43040 | C32: =IF(Rankings!C35<=2,1,0) -> 0 | D32: =IF(Rankings!D35<=2,1,0) -> 0 | E32: =IF(Rankings!E35<=2,1,0) -> 0 | F32: =IF(Rankings!F35<=2,1,0) -> 0 | G32: =IF(Rankings!G35<=2,1,0) -> 0 | H32: =IF(Rankings!H35<=2,1,0) -> 1 | I32: =IF(Rankings!I35<=2,1,0) -> 1 | J32: =IF(Rankings!J35<=2,1,0) -> 0 | K32: =SUM(C32:J32) -> 2 | L32: =SUMPRODUCT(C32:J32,Returns!B36:I36)/K32 -> 0.25527342 | M32: 0 | N32: 0 | O32: =L32+M32+N32 -> 0.25527342 | P32: =P31*(1+O32) -> 1.9170155 | Q32: =MAX($P$5:P32) -> 3.1505472 | R32: =P32/Q32-1 -> -0.39152937 | S32: =O32-Benchmark_RF!D32 -> 0.25041306
A33: 36 | B33: =Returns!A37 -> 43070 | C33: =IF(Rankings!C35<=2,1,0) -> 0 | D33: =IF(Rankings!D35<=2,1,0) -> 0 | E33: =IF(Rankings!E35<=2,1,0) -> 0 | F33: =IF(Rankings!F35<=2,1,0) -> 0 | G33: =IF(Rankings!G35<=2,1,0) -> 0 | H33: =IF(Rankings!H35<=2,1,0) -> 1 | I33: =IF(Rankings!I35<=2,1,0) -> 1 | J33: =IF(Rankings!J35<=2,1,0) -> 0 | K33: =SUM(C33:J33) -> 2 | L33: =SUMPRODUCT(C33:J33,Returns!B37:I37)/K33 -> -0.029051268 | M33: 0 | N33: 0 | O33: =L33+M33+N33 -> -0.029051268 | P33: =P32*(1+O33) -> 1.8613237 | Q33: =MAX($P$5:P33) -> 3.1505472 | R33: =P33/Q33-1 -> -0.40920621 | S33: =O33-Benchmark_RF!D33 -> -0.033911708
A34: 37 | B34: =Returns!A38 -> 43101 | C34: =IF(Rankings!C35<=2,1,0) -> 0 | D34: =IF(Rankings!D35<=2,1,0) -> 0 | E34: =IF(Rankings!E35<=2,1,0) -> 0 | F34: =IF(Rankings!F35<=2,1,0) -> 0 | G34: =IF(Rankings!G35<=2,1,0) -> 0 | H34: =IF(Rankings!H35<=2,1,0) -> 1 | I34: =IF(Rankings!I35<=2,1,0) -> 1 | J34: =IF(Rankings!J35<=2,1,0) -> 0 | K34: =SUM(C34:J34) -> 2 | L34: =SUMPRODUCT(C34:J34,Returns!B38:I38)/K34 -> 0.058860759 | M34: 0 | N34: 0 | O34: =L34+M34+N34 -> 0.058860759 | P34: =P33*(1+O34) -> 1.9708827 | Q34: =MAX($P$5:P34) -> 3.1505472 | R34: =P34/Q34-1 -> -0.37443164 | S34: =O34-Benchmark_RF!D34 -> 0.053835347
A35: 38 | B35: =Returns!A39 -> 43132 | C35: =IF(Rankings!C35<=2,1,0) -> 0 | D35: =IF(Rankings!D35<=2,1,0) -> 0 | E35: =IF(Rankings!E35<=2,1,0) -> 0 | F35: =IF(Rankings!F35<=2,1,0) -> 0 | G35: =IF(Rankings!G35<=2,1,0) -> 0 | H35: =IF(Rankings!H35<=2,1,0) -> 1 | I35: =IF(Rankings!I35<=2,1,0) -> 1 | J35: =IF(Rankings!J35<=2,1,0) -> 0 | K35: =SUM(C35:J35) -> 2 | L35: =SUMPRODUCT(C35:J35,Returns!B39:I39)/K35 -> 0.010483002 | M35: 0 | N35: 0 | O35: =L35+M35+N35 -> 0.010483002 | P35: =P34*(1+O35) -> 1.9915434 | Q35: =MAX($P$5:P35) -> 3.1505472 | R35: =P35/Q35-1 -> -0.36787381 | S35: =O35-Benchmark_RF!D35 -> 0.0054321997
A36: 39 | B36: =Returns!A40 -> 43160 | C36: =IF(Rankings!C35<=2,1,0) -> 0 | D36: =IF(Rankings!D35<=2,1,0) -> 0 | E36: =IF(Rankings!E35<=2,1,0) -> 0 | F36: =IF(Rankings!F35<=2,1,0) -> 0 | G36: =IF(Rankings!G35<=2,1,0) -> 0 | H36: =IF(Rankings!H35<=2,1,0) -> 1 | I36: =IF(Rankings!I35<=2,1,0) -> 1 | J36: =IF(Rankings!J35<=2,1,0) -> 0 | K36: =SUM(C36:J36) -> 2 | L36: =SUMPRODUCT(C36:J36,Returns!B40:I40)/K36 -> 0.21335634 | M36: 0 | N36: 0 | O36: =L36+M36+N36 -> 0.21335634 | P36: =P35*(1+O36) -> 2.4164519 | Q36: =MAX($P$5:P36) -> 3.1505472 | R36: =P36/Q36-1 -> -0.23300567 | S36: =O36-Benchmark_RF!D36 -> 0.20828433
A37: 40 | B37: =Returns!A41 -> 43191 | C37: =IF(Rankings!C35<=2,1,0) -> 0 | D37: =IF(Rankings!D35<=2,1,0) -> 0 | E37: =IF(Rankings!E35<=2,1,0) -> 0 | F37: =IF(Rankings!F35<=2,1,0) -> 0 | G37: =IF(Rankings!G35<=2,1,0) -> 0 | H37: =IF(Rankings!H35<=2,1,0) -> 1 | I37: =IF(Rankings!I35<=2,1,0) -> 1 | J37: =IF(Rankings!J35<=2,1,0) -> 0 | K37: =SUM(C37:J37) -> 2 | L37: =SUMPRODUCT(C37:J37,Returns!B41:I41)/K37 -> 0.023455402 | M37: 0 | N37: 0 | O37: =L37+M37+N37 -> 0.023455402 | P37: =P36*(1+O37) -> 2.4731307 | Q37: =MAX($P$5:P37) -> 3.1505472 | R37: =P37/Q37-1 -> -0.21501551 | S37: =O37-Benchmark_RF!D37 -> 0.018400895
A38: 41 | B38: =Returns!A42 -> 43221 | C38: =IF(Rankings!C35<=2,1,0) -> 0 | D38: =IF(Rankings!D35<=2,1,0) -> 0 | E38: =IF(Rankings!E35<=2,1,0) -> 0 | F38: =IF(Rankings!F35<=2,1,0) -> 0 | G38: =IF(Rankings!G35<=2,1,0) -> 0 | H38: =IF(Rankings!H35<=2,1,0) -> 1 | I38: =IF(Rankings!I35<=2,1,0) -> 1 | J38: =IF(Rankings!J35<=2,1,0) -> 0 | K38: =SUM(C38:J38) -> 2 | L38: =SUMPRODUCT(C38:J38,Returns!B42:I42)/K38 -> 0.019805924 | M38: 0 | N38: 0 | O38: =L38+M38+N38 -> 0.019805924 | P38: =P37*(1+O38) -> 2.5221134 | Q38: =MAX($P$5:P38) -> 3.1505472 | R38: =P38/Q38-1 -> -0.19946817 | S38: =O38-Benchmark_RF!D38 -> 0.014734389
A39: 42 | B39: =Returns!A43 -> 43252 | C39: =IF(Rankings!C35<=2,1,0) -> 0 | D39: =IF(Rankings!D35<=2,1,0) -> 0 | E39: =IF(Rankings!E35<=2,1,0) -> 0 | F39: =IF(Rankings!F35<=2,1,0) -> 0 | G39: =IF(Rankings!G35<=2,1,0) -> 0 | H39: =IF(Rankings!H35<=2,1,0) -> 1 | I39: =IF(Rankings!I35<=2,1,0) -> 1 | J39: =IF(Rankings!J35<=2,1,0) -> 0 | K39: =SUM(C39:J39) -> 2 | L39: =SUMPRODUCT(C39:J39,Returns!B43:I43)/K39 -> 0.042045583 | M39: 0 | N39: 0 | O39: =L39+M39+N39 -> 0.042045583 | P39: =P38*(1+O39) -> 2.6281571 | Q39: =MAX($P$5:P39) -> 3.1505472 | R39: =P39/Q39-1 -> -0.16580934 | S39: =O39-Benchmark_RF!D39 -> 0.036579997
A40: 43 | B40: =Returns!A44 -> 43282 | C40: =IF(Rankings!C35<=2,1,0) -> 0 | D40: =IF(Rankings!D35<=2,1,0) -> 0 | E40: =IF(Rankings!E35<=2,1,0) -> 0 | F40: =IF(Rankings!F35<=2,1,0) -> 0 | G40: =IF(Rankings!G35<=2,1,0) -> 0 | H40: =IF(Rankings!H35<=2,1,0) -> 1 | I40: =IF(Rankings!I35<=2,1,0) -> 1 | J40: =IF(Rankings!J35<=2,1,0) -> 0 | K40: =SUM(C40:J40) -> 2 | L40: =SUMPRODUCT(C40:J40,Returns!B44:I44)/K40 -> 0.068663569 | M40: 0 | N40: 0 | O40: =L40+M40+N40 -> 0.068663569 | P40: =P39*(1+O40) -> 2.8086157 | Q40: =MAX($P$5:P40) -> 3.1505472 | R40: =P40/Q40-1 -> -0.10853084 | S40: =O40-Benchmark_RF!D40 -> 0.062446226
A41: 44 | B41: =Returns!A45 -> 43313 | C41: =IF(Rankings!C47<=2,1,0) -> 1 | D41: =IF(Rankings!D47<=2,1,0) -> 0 | E41: =IF(Rankings!E47<=2,1,0) -> 0 | F41: =IF(Rankings!F47<=2,1,0) -> 0 | G41: =IF(Rankings!G47<=2,1,0) -> 0 | H41: =IF(Rankings!H47<=2,1,0) -> 1 | I41: =IF(Rankings!I47<=2,1,0) -> 0 | J41: =IF(Rankings!J47<=2,1,0) -> 0 | K41: =SUM(C41:J41) -> 2 | L41: =SUMPRODUCT(C41:J41,Returns!B45:I45)/K41 -> -0.0044257353 | M41: =-2*Assumptions!$B$13 -> -0.007 | N41: =-Assumptions!$B$16*MAX(0,(1+O29)*(1+O30)*(1+O31)*(1+O32)*(1+O33)*(1+O34)*(1+O35)*(1+O36)*(1+O37)*(1+O38)*(1+O39)*(1+O40)-1) -> 0 | O41: =L41+M41+N41 -> -0.011425735 | P41: =P40*(1+O41) -> 2.7765252 | Q41: =MAX($P$5:P41) -> 3.1505472 | R41: =P41/Q41-1 -> -0.11871653 | S41: =O41-Benchmark_RF!D41 -> -0.017665417
...

Sheet S_Top2_SemiAnnual
A1: Scenario: Top 2 stocks, SemiAnnual rebalancing (hold 6 months)
A2: Holdings flag in each row = lookup of Rankings at the governing formation-month (decision row), held constant until next rebalance. Decision i -> holding starts month i+1.
A4: Month (j) | B4: Date | C4: OGDC | D4: MEBL | E4: EFERT | F4: MCB | G4: LUCK | H4: FFC | I4: SAZEW | J4: MARI | K4: Held N | L4: Gross Return | M4: Txn Cost | N4: CGT | O4: Net Return | P4: Growth of Rs.1 | Q4: Running Max | R4: Drawdown | S4: Excess Return
A5: 8 | B5: =Returns!A9 -> 42217 | C5: =IF(Rankings!C11<=2,1,0) -> 0 | D5: =IF(Rankings!D11<=2,1,0) -> 0 | E5: =IF(Rankings!E11<=2,1,0) -> 0 | F5: =IF(Rankings!F11<=2,1,0) -> 0 | G5: =IF(Rankings!G11<=2,1,0) -> 1 | H5: =IF(Rankings!H11<=2,1,0) -> 1 | I5: =IF(Rankings!I11<=2,1,0) -> 0 | J5: =IF(Rankings!J11<=2,1,0) -> 0 | K5: =SUM(C5:J5) -> 2 | L5: =SUMPRODUCT(C5:J5,Returns!B9:I9)/K5 -> -0.056681129 | M5: =-2*Assumptions!$B$13 -> -0.007 | N5: 0 | O5: =L5+M5+N5 -> -0.063681129 | P5: =1*(1+O5) -> 0.93631887 | Q5: =MAX($P$5:P5) -> 0.93631887 | R5: =P5/Q5-1 -> 0 | S5: =O5-Benchmark_RF!D5 -> -0.06928106
A6: 9 | B6: =Returns!A10 -> 42248 | C6: =IF(Rankings!C11<=2,1,0) -> 0 | D6: =IF(Rankings!D11<=2,1,0) -> 0 | E6: =IF(Rankings!E11<=2,1,0) -> 0 | F6: =IF(Rankings!F11<=2,1,0) -> 0 | G6: =IF(Rankings!G11<=2,1,0) -> 1 | H6: =IF(Rankings!H11<=2,1,0) -> 1 | I6: =IF(Rankings!I11<=2,1,0) -> 0 | J6: =IF(Rankings!J11<=2,1,0) -> 0 | K6: =SUM(C6:J6) -> 2 | L6: =SUMPRODUCT(C6:J6,Returns!B10:I10)/K6 -> -0.050873779 | M6: 0 | N6: 0 | O6: =L6+M6+N6 -> -0.050873779 | P6: =P5*(1+O6) -> 0.88868479 | Q6: =MAX($P$5:P6) -> 0.93631887 | R6: =P6/Q6-1 -> -0.050873779 | S6: =O6-Benchmark_RF!D6 -> -0.056108962
A7: 10 | B7: =Returns!A11 -> 42278 | C7: =IF(Rankings!C11<=2,1,0) -> 0 | D7: =IF(Rankings!D11<=2,1,0) -> 0 | E7: =IF(Rankings!E11<=2,1,0) -> 0 | F7: =IF(Rankings!F11<=2,1,0) -> 0 | G7: =IF(Rankings!G11<=2,1,0) -> 1 | H7: =IF(Rankings!H11<=2,1,0) -> 1 | I7: =IF(Rankings!I11<=2,1,0) -> 0 | J7: =IF(Rankings!J11<=2,1,0) -> 0 | K7: =SUM(C7:J7) -> 2 | L7: =SUMPRODUCT(C7:J7,Returns!B11:I11)/K7 -> 0.01976487 | M7: 0 | N7: 0 | O7: =L7+M7+N7 -> 0.01976487 | P7: =P6*(1+O7) -> 0.90624953 | Q7: =MAX($P$5:P7) -> 0.93631887 | R7: =P7/Q7-1 -> -0.032114423 | S7: =O7-Benchmark_RF!D7 -> 0.014657635
